<?xml version='1.0'?>
<sdf version='1.4'>
	<model name="bluethread_8mm">
		<include>
			<uri>model://bt_component</uri>
			<name>comp_1</name>
			<pose>0 0 0 0 0 0</pose>
		</include>
		<include>
			<uri>model://bt_component</uri>
			<name>comp_2</name>
			<pose>0 0 0.001 0 0 0</pose>
		</include>
		<joint name="j1-2" type="revolute2">
			<parent>comp_1::link</parent>
			<child>comp_2::link</child>
			<pose>0 0 -0.0005 0 0 0</pose>
			<axis>
				<xyz>0 1.0 0</xyz>
			</axis>
			<axis2>
				<xyz>1.0 0 0</xyz>
			</axis2>
		</joint>
		<include>
			<uri>model://bt_component</uri>
			<name>comp_3</name>
			<pose>0 0 0.002 0 0 0</pose>
		</include>
		<joint name="j2-3" type="revolute">
			<parent>comp_2::link</parent>
			<child>comp_3::link</child>
			<pose>0 0 -0.0005 0 0 0</pose>
			<axis>
				<xyz>0 1.0 0</xyz>
			</axis>
			<axis2>
				<xyz>1.0 0 0</xyz>
			</axis2>
		</joint>
		<include>
			<uri>model://bt_component</uri>
			<name>comp_4</name>
			<pose>0 0 0.003 0 0 0</pose>
		</include>
		<joint name="j3-4" type="revolute">
			<parent>comp_3::link</parent>
			<child>comp_4::link</child>
			<pose>0 0 -0.0005 0 0 0</pose>
			<axis>
				<xyz>0 1.0 0</xyz>
			</axis>
			<axis2>
				<xyz>1.0 0 0</xyz>
			</axis2>
		</joint>
		<include>
			<uri>model://bt_component</uri>
			<name>comp_5</name>
			<pose>0 0 0.004 0 0 0</pose>
		</include>
		<joint name="j4-5" type="revolute">
			<parent>comp_4::link</parent>
			<child>comp_5::link</child>
			<pose>0 0 -0.0005 0 0 0</pose>
			<axis>
				<xyz>0 1.0 0</xyz>
			</axis>
			<axis2>
				<xyz>1.0 0 0</xyz>
			</axis2>
		</joint>
		<include>
			<uri>model://bt_component</uri>
			<name>comp_6</name>
			<pose>0 0 0.005 0 0 0</pose>
		</include>
		<joint name="j5-6" type="revolute">
			<parent>comp_5::link</parent>
			<child>comp_6::link</child>
			<pose>0 0 -0.0005 0 0 0</pose>
			<axis>
				<xyz>0 1.0 0</xyz>
			</axis>
			<axis2>
				<xyz>1.0 0 0</xyz>
			</axis2>
		</joint>
		<include>
			<uri>model://bt_component</uri>
			<name>comp_7</name>
			<pose>0 0 0.006 0 0 0</pose>
		</include>
		<joint name="j6-7" type="revolute">
			<parent>comp_6::link</parent>
			<child>comp_7::link</child>
			<pose>0 0 -0.0005 0 0 0</pose>
			<axis>
				<xyz>0 1.0 0</xyz>
			</axis>
			<axis2>
				<xyz>1.0 0 0</xyz>
			</axis2>
		</joint>
		<include>
			<uri>model://bt_component</uri>
			<name>comp_8</name>
			<pose>0 0 0.007 0 0 0</pose>
		</include>
		<joint name="j7-8" type="revolute">
			<parent>comp_7::link</parent>
			<child>comp_8::link</child>
			<pose>0 0 -0.0005 0 0 0</pose>
			<axis>
				<xyz>0 1.0 0</xyz>
			</axis>
			<axis2>
				<xyz>1.0 0 0</xyz>
			</axis2>
		</joint>
	</model>
</sdf>
